Workbook
Name Z_BE54E0AD_3725_4423_92D7_4F1C045BE1BC_.wvu.Cols: 'Create Discount'!$E:$E
Name Z_BE54E0AD_3725_4423_92D7_4F1C045BE1BC_.wvu.Cols: Register!$E:$E
Name Z_6F1DCD5D_5DAC_4817_BF40_2B66F6F593E6_.wvu.Cols: 'ActivateDeactivate Shop'!$E:$E
Name Z_2C0D9096_8D85_462A_A9B5_0B488ADB4269_.wvu.Cols: 'View Reports (Operator)'!$E:$E
Name Z_BE54E0AD_3725_4423_92D7_4F1C045BE1BC_.wvu.Cols: 'View Report Detail (Operator)'!$E:$E
Name Z_2C0D9096_8D85_462A_A9B5_0B488ADB4269_.wvu.Cols: 'View Blog Reports'!$E:$E
Name Z_2C0D9096_8D85_462A_A9B5_0B488ADB4269_.wvu.Cols: EditProduct!$E:$E
Name Z_6F1DCD5D_5DAC_4817_BF40_2B66F6F593E6_.wvu.Cols: 'ApproveReject Shipper register'!$E:$E
Name Z_2C0D9096_8D85_462A_A9B5_0B488ADB4269_.wvu.Cols: 'View feedback list'!$E:$E
Name Z_6F1DCD5D_5DAC_4817_BF40_2B66F6F593E6_.wvu.Cols: 'Request Order return'!$E:$E
Name Z_BE54E0AD_3725_4423_92D7_4F1C045BE1BC_.wvu.Cols: 'ActivateDeactivate Shipper'!$E:$E
Name Z_6F1DCD5D_5DAC_4817_BF40_2B66F6F593E6_.wvu.Cols: 'ActivateDeactivate Shipper'!$E:$E
Name Z_BE54E0AD_3725_4423_92D7_4F1C045BE1BC_.wvu.Cols: 'Reject Order'!$E:$E
Name Z_2C0D9096_8D85_462A_A9B5_0B488ADB4269_.wvu.Cols: 'Apply Voucher'!$E:$E
Name Z_BE54E0AD_3725_4423_92D7_4F1C045BE1BC_.wvu.Cols: 'Accept Order'!$E:$E
Name Z_2C0D9096_8D85_462A_A9B5_0B488ADB4269_.wvu.Cols: 'View Shops revenue'!$E:$E
Name Z_BE54E0AD_3725_4423_92D7_4F1C045BE1BC_.wvu.Cols: 'View Shop Reports(Shopkeeper)'!$E:$E
Name Z_6F1DCD5D_5DAC_4817_BF40_2B66F6F593E6_.wvu.Cols: 'Auto count Rating for Shop'!$E:$E
Name Z_2C0D9096_8D85_462A_A9B5_0B488ADB4269_.wvu.PrintArea: Statistics!$A:$I
Name Z_2C0D9096_8D85_462A_A9B5_0B488ADB4269_.wvu.Cols: 'ActivateDeactivate Shipper'!$E:$E
Name Z_BE54E0AD_3725_4423_92D7_4F1C045BE1BC_.wvu.Cols: 'Get location from google Map'!$E:$E
Name Z_6F1DCD5D_5DAC_4817_BF40_2B66F6F593E6_.wvu.Cols: 'Confirm Order Receive(Customer)'!$E:$E
Name Z_6F1DCD5D_5DAC_4817_BF40_2B66F6F593E6_.wvu.Cols: 'View Shops revenue'!$E:$E
Name Z_6F1DCD5D_5DAC_4817_BF40_2B66F6F593E6_.wvu.Cols: 'View feedback list'!$E:$E
Name Z_6F1DCD5D_5DAC_4817_BF40_2B66F6F593E6_.wvu.Cols: 'View Shop Dashboard'!$E:$E
Name Z_BE54E0AD_3725_4423_92D7_4F1C045BE1BC_.wvu.Cols: AddProduct!$E:$E
Name Z_2C0D9096_8D85_462A_A9B5_0B488ADB4269_.wvu.Cols: 'Disable Voucher'!$E:$E
Name Z_BE54E0AD_3725_4423_92D7_4F1C045BE1BC_.wvu.Cols: 'View Discount List'!$E:$E
Name Z_6F1DCD5D_5DAC_4817_BF40_2B66F6F593E6_.wvu.Cols: 'Create Discount'!$E:$E
Name Z_6F1DCD5D_5DAC_4817_BF40_2B66F6F593E6_.wvu.Cols: 'View Order List (Customer)'!$E:$E
Name Z_2C0D9096_8D85_462A_A9B5_0B488ADB4269_.wvu.Cols: Register!$E:$E
Name Z_6F1DCD5D_5DAC_4817_BF40_2B66F6F593E6_.wvu.Cols: 'Disable Voucher'!$E:$E
Name Z_2C0D9096_8D85_462A_A9B5_0B488ADB4269_.wvu.Cols: 'Create Discount'!$E:$E
Name Z_6F1DCD5D_5DAC_4817_BF40_2B66F6F593E6_.wvu.Cols: 'Submit Feedback '!$E:$E
Name Z_BE54E0AD_3725_4423_92D7_4F1C045BE1BC_.wvu.Cols: ViewProductList!$E:$E
Name Z_BE54E0AD_3725_4423_92D7_4F1C045BE1BC_.wvu.Cols: 'Auto count Rating for Shop'!$E:$E
Name Z_2C0D9096_8D85_462A_A9B5_0B488ADB4269_.wvu.Cols: 'Change Order Status (Shopkeeper'!$E:$E
Name Z_BE54E0AD_3725_4423_92D7_4F1C045BE1BC_.wvu.Cols: 'View Voucher List'!$E:$E
Name Z_6F1DCD5D_5DAC_4817_BF40_2B66F6F593E6_.wvu.Cols: 'Resolve Order Return Request'!$E:$E
Name Z_BE54E0AD_3725_4423_92D7_4F1C045BE1BC_.wvu.Cols: 'ApproveReject Shipper register'!$E:$E
Name Z_BE54E0AD_3725_4423_92D7_4F1C045BE1BC_.wvu.Cols: 'Choose Payment Method'!$E:$E
Name Z_6F1DCD5D_5DAC_4817_BF40_2B66F6F593E6_.wvu.Cols: Login!$E:$E
Name Z_6F1DCD5D_5DAC_4817_BF40_2B66F6F593E6_.wvu.Cols: 'ActivateDeactivate account'!$E:$E
Name Z_2C0D9096_8D85_462A_A9B5_0B488ADB4269_.wvu.Cols: 'Change Order Status (Shipper)'!$E:$E
Name Z_6F1DCD5D_5DAC_4817_BF40_2B66F6F593E6_.wvu.Cols: 'ApproveReject shop register'!$E:$E
Name Z_BE54E0AD_3725_4423_92D7_4F1C045BE1BC_.wvu.Cols: 'Apply Voucher'!$E:$E
Name Z_BE54E0AD_3725_4423_92D7_4F1C045BE1BC_.wvu.Cols: 'Choose Shipping Method'!$E:$E
Name Z_2C0D9096_8D85_462A_A9B5_0B488ADB4269_.wvu.Cols: 'Delete feedback'!$E:$E
Name Z_2C0D9096_8D85_462A_A9B5_0B488ADB4269_.wvu.Cols: 'Check Out'!$E:$E
Name Z_2C0D9096_8D85_462A_A9B5_0B488ADB4269_.wvu.Cols: 'Recommend food by type for cust'!$E:$E
Name Z_2C0D9096_8D85_462A_A9B5_0B488ADB4269_.wvu.Cols: 'Confirm Order Receive(Customer)'!$E:$E
Name Z_6F1DCD5D_5DAC_4817_BF40_2B66F6F593E6_.wvu.Cols: 'Recommend food by type for cust'!$E:$E
Name Z_6F1DCD5D_5DAC_4817_BF40_2B66F6F593E6_.wvu.Cols: 'View Voucher List'!$E:$E
Name Z_2C0D9096_8D85_462A_A9B5_0B488ADB4269_.wvu.Cols: 'Disable Discount'!$E:$E
Name Z_BE54E0AD_3725_4423_92D7_4F1C045BE1BC_.wvu.Cols: 'Shipper Register'!$E:$E
Name Z_BE54E0AD_3725_4423_92D7_4F1C045BE1BC_.wvu.Cols: 'Disable Voucher'!$E:$E
Name Z_BE54E0AD_3725_4423_92D7_4F1C045BE1BC_.wvu.Cols: 'Submit Feedback '!$E:$E
Name Z_BE54E0AD_3725_4423_92D7_4F1C045BE1BC_.wvu.Cols: 'Delete feedback'!$E:$E
Name Z_2C0D9096_8D85_462A_A9B5_0B488ADB4269_.wvu.Cols: 'View Blog Report Detail'!$E:$E
Name Z_6F1DCD5D_5DAC_4817_BF40_2B66F6F593E6_.wvu.Cols: 'Change Order Status (Shopkeeper'!$E:$E

Sheet Guideline
A1: Guideline to make and understand Unit Test Case
A3: 1. Overview
A4: - In the template, Unit test cases are based on functions. Each sheet presents test cases for one function.
A5: - Cover: General information of the project and Unit Test cases
A6: - FunctionList: The list of Classes and Functions in the document. + To control that the number of Unit TC meets customer's requirement or the norm, user should fill value for 'Normal number of Test cases/KLOC'.
A7: + Click on Function link to open the related Test cases of the function. Note: You should create new Function sheet before creating the link
A8: - Test Report: provive the overview results of Functions Unit test: Test coverage, Test successful coverage (Summary, for normal/abnormal/boundary cases)
A9: Note: Should check the formula of "Sub Total" if you add more functions
A11: 2. Content in Test function sheet
A12: 2.1 Combination of test cases.
A13: - To verify that number of Unit TC meets customer's requirement or not. User has to fill number LOC of tested function and fill value of 'Normal number test cases/KLOC' item in FunctionList sheet, which is required by customer or normal value. The number of lacked TC is shown in 'Lack of test cases' item.
A14: - If the number of Unit TC does not meet the requirement, creator should explain the reasons.
... A46: - Test requirement: Brief description about requirements which are tested in this function, it is not mandatory.

Sheet Cover
B2: UNIT TEST DOCUMENT
A4: Project Name | B4: FastF&B | E4: Creator | F4: AnhDQ
A5: Project Code | B5: FFB | E5: Issue Date | F5: 45698
A6: Document Code | B6: =B5&"_"&"UnitTest"&"_"&"v1.0" -> FFB_UnitTest_v1.0 | E6: Version | F6: 1.1.2
A9: Record of change
A10: Effective Date | B10: Version | C10: Change Item | D10: *A,D,M | E10: Change description | F10: Reference
A11: 45698 | B11: 1.0 | D11: C | E11: Create report
A12: 45700 | B12: 1.0 | D12: A | E12: Add MethodList and Statistics form for iter 1
A13: 45701 | B13: 1.0 | D13: A | E13: Add all the sheet for iter 1
A14: 45702 | B14: 1.0 | D14: A | E14: Add all the test case for modules for iter 1
A15: 45720 | B15: 1.1 | D15: A | E15: Add MethodList and Statistics form for iter 2
A16: 45720 | B16: 1.1 | D16: A | E16: Add all the sheet for iter 2
A17: 45721 | B17: 1.1 | D17: A | E17: Add all the test case for modules for iter 2
A18: 45736 | B18: 1.2 | D18: A | E18: Add MethodList and Statistics form for iter 3
A19: 45737 | B19: 1.2 | D19: A | E19: Add all the sheet for iter 3
A20: 45738 | B20: 1.2 | D20: A | E20: Add all the test case for modules for iter 3

Sheet MethodList
C2: Method List
A4: Project Name | C4: =Cover!B4 -> FastF&B
A5: Project Code | C5: =Cover!B5 -> FFB
A6: Test Environment Setup Description | C6: 1. Server 2. MySql Database 3. Web Browser for React 4.Mobile App for Flutter 5.Postman
A8: No | B8: Module Name | C8: Method Name | D8: Sheet Name | E8: Description | F8: Pre-Condition
A9: 1 | B9: Account Management | C9: Login | D9: Login | F9: Already have an account in the system database
A10: 2 | B10: Account Management | C10: Logout | D10: Logout | F10: Logged into the system
A11: 3 | B11: Account Management | C11: Register | D11: Register | F11: Format password, email, phone number when entering
A12: 4 | B12: Account Management | C12: View profile | D12: View profile | F12: Logged into the system
A13: 5 | B13: Account Management | C13: Edit profile | D13: Edit profile | F13: Logged into the system
A14: 6 | B14: Account Management | C14: Change password | D14: Change password | F14: Logged into the system
A15: 7 | B15: Account Management | C15: Forgot password | D15: Forgot password | F15: Account must be registered with phone number in db
A16: 8 | B16: Blog Management | C16: View Blog List | D16: View Blog List | F16: Logged into the system
A17: 9 | B17: Blog Management | C17: View Blog Detail | D17: View Blog Detail | F17: Logged into the system
A18: 10 | B18: Blog Management | C18: Add Blog Post | D18: Add Blog Post | F18: Logged into the system
A19: 11 | B19: Blog Management | C19: Edit Blog Post | D19: Edit Blog Post | F19: Logged in to the system, is the owner of at least 1 blog
A20: 12 | B20: Blog Management | C20: Delete Blog Post | D20: Delete Blog Post | F20: Logged in to the system, is the owner of at least 1 blog
... A90: 82 | B90: Discount Management | C90: Disable Discount | D90: View Discount List | F90: Logged into the system

Sheet Statistics
A2: UNIT TEST REPORT
A4: Project Name | B4: =Cover!B4 -> FastF&B | D4: Creator | F4: AnhDQ
A5: Project Code | B5: =Cover!B5 -> FFB | D5: Reviewer/Approver | F5: NGUYENT
A6: Document Code | B6: =B5&"_"&"UnitTest"&"_"&"v1.2" -> FFB_UnitTest_v1.2 | D6: Issue Date | F6: 45698
A7: Notes
A11: No | B11: Function code | C11: Passed | D11: Failed | E11: Untested | F11: N | G11: A | H11: B | I11: Total Test Cases
A12: 1 | B12: Login | C12: =Login!A5 -> 4 | D12: =Login!C5 -> 0 | E12: =Login!F5 -> 0 | F12: =Login!L5 -> 1 | G12: =Login!M5 -> 3 | H12: =Login!N5 -> 0 | I12: =Login!O5 -> 4
A13: 2 | B13: Logout | C13: =Logout!A5 -> 1 | D13: =Logout!C5 -> 0 | E13: =Logout!F5 -> 0 | F13: =Logout!L5 -> 1 | G13: =Logout!M5 -> 0 | H13: =Logout!N5 -> 0 | I13: =Logout!O5 -> 1
A14: 3 | B14: Register | C14: =Register!A5 -> 18 | D14: =Register!C5 -> 0 | E14: =Register!F5 -> 0 | F14: =Register!L5 -> 1 | G14: =Register!M5 -> 17 | H14: =Register!N5 -> 0 | I14: =Register!O5 -> 18
A15: 4 | B15: View profile | C15: =ViewProfile!A5 -> 2 | D15: =ViewProfile!C5 -> 0 | E15: =ViewProfile!F5 -> 0 | F15: =ViewProfile!L5 -> 1 | G15: =ViewProfile!M5 -> 1 | H15: =ViewProfile!N5 -> 0 | I15: =ViewProfile!O5 -> 2
A16: 5 | B16: Edit profile | C16: =EditProfile!A5 -> 6 | D16: =EditProfile!C5 -> 0 | E16: =EditProfile!F5 -> 0 | F16: =EditProfile!L5 -> 1 | G16: =EditProfile!M5 -> 5 | H16: =EditProfile!N5 -> 0 | I16: =EditProfile!O5 -> 6
A17: 6 | B17: Change password | C17: =ChangePassword!A5 -> 4 | D17: =ChangePassword!C5 -> 0 | E17: =ChangePassword!F5 -> 0 | F17: =ChangePassword!L5 -> 1 | G17: =ChangePassword!M5 -> 3 | H17: =ChangePassword!N5 -> 0 | I17: =ChangePassword!O5 -> 4
A18: 7 | B18: Forgot password | C18: =Forgotpassword!A5 -> 4 | D18: =Forgotpassword!C5 -> 0 | E18: =Forgotpassword!F5 -> 0 | F18: =Forgotpassword!L5 -> 1 | G18: =Forgotpassword!M5 -> 3 | H18: =Forgotpassword!N5 -> 0 | I18: =Forgotpassword!O5 -> 4
A19: 8 | B19: View Blog List | C19: =ViewBlogList!A5 -> 2 | D19: =ViewBlogList!C5 -> 0 | E19: =ViewBlogList!F5 -> 0 | F19: =ViewBlogList!L5 -> 2 | G19: =ViewBlogList!M5 -> 0 | H19: =ViewBlogList!N5 -> 0 | I19: =ViewBlogList!O5 -> 2
A20: 9 | B20: View Blog Detail | C20: =ViewProfile!O5 -> 2 | D20: =ViewProfile!C5 -> 0 | E20: =ViewProfile!F5 -> 0 | F20: =ViewProfile!L5 -> 1 | G20: =ViewProfile!M5 -> 1 | H20: =ViewProfile!N5 -> 0 | I20: =ViewProfile!O5 -> 2
A21: 10 | B21: Add Blog Post | C21: =AddBlog!A5 -> 3 | D21: =AddBlog!C5 -> 0 | E21: =AddBlog!F5 -> 0 | F21: =AddBlog!L5 -> 2 | G21: =AddBlog!M5 -> 1 | H21: =AddBlog!N5 -> 0 | I21: =AddBlog!O5 -> 3
A22: 11 | B22: Edit Blog Post | C22: =EditBlog!O5 -> 4 | D22: =EditBlog!C5 -> 0 | E22: =EditBlog!F5 -> 0 | F22: =EditBlog!L5 -> 4 | G22: =EditBlog!M5 -> 0 | H22: =EditBlog!N5 -> 0 | I22: =EditBlog!O5 -> 4
A23: 12 | B23: Delete Blog Post | C23: =DeleteBlog!O5 -> 1 | D23: =DeleteBlog!C5 -> 0 | E23: =DeleteBlog!F5 -> 0 | F23: =DeleteBlog!L5 -> 1 | G23: =DeleteBlog!M5 -> 0 | H23: =DeleteBlog!N5 -> 0 | I23: =DeleteBlog!O5 -> 1
A24: 13 | B24: Comment/Reply on Blog | C24: =CommentReplyonBlog!A5 -> 8 | D24: =CommentReplyonBlog!C5 -> 0 | E24: =CommentReplyonBlog!F5 -> 0 | F24: =CommentReplyonBlog!L5 -> 2 | G24: =CommentReplyonBlog!M5 -> 4 | H24: =CommentReplyonBlog!N5 -> 2 | I24: =CommentReplyonBlog!O5 -> 8
A25: 14 | B25: View Shop Product (Shopkeeper) | C25: =ViewShopProduct!A5 -> 5 | D25: =ViewShopProduct!C5 -> 0 | E25: =ViewShopProduct!F5 -> 0 | F25: =ViewShopProduct!L5 -> 5 | G25: =ViewShopProduct!M5 -> 0 | H25: =ViewShopProduct!N5 -> 0 | I25: =ViewShopProduct!O5 -> 5
A26: 15 | B26: Add Product | C26: =AddProduct!A5 -> 6 | D26: =AddProduct!C5 -> 0 | E26: =AddProduct!F5 -> 0 | F26: =AddProduct!L5 -> 1 | G26: =AddProduct!M5 -> 3 | H26: =AddProduct!N5 -> 2 | I26: =AddProduct!O5 -> 6
A27: 16 | B27: Edit Product | C27: =EditProduct!A5 -> 6 | D27: =EditProduct!C5 -> 0 | E27: =EditProduct!F5 -> 0 | F27: =EditProduct!L5 -> 1 | G27: =EditProduct!M5 -> 3 | H27: =EditProduct!N5 -> 2 | I27: =EditProduct!O5 -> 6
A28: 17 | B28: Delete Product | C28: =DeleteProduct!A5 -> 1 | D28: =DeleteProduct!C5 -> 0 | E28: =DeleteProduct!F5 -> 0 | F28: =DeleteProduct!L5 -> 1 | G28: =DeleteProduct!M5 -> 0 | H28: =DeleteProduct!N5 -> 0 | I28: =DeleteProduct!O5 -> 1
A29: 18 | B29: View Product List | C29: =ViewProductList!A5 -> 4 | D29: =ViewProductList!C5 -> 0 | E29: =ViewProductList!F5 -> 0 | F29: =ViewProductList!L5 -> 3 | G29: =ViewProductList!M5 -> 1 | H29: =ViewProductList!N5 -> 0 | I29: =ViewProductList!O5 -> 4
A30: 19 | B30: View Product Detail (Shopkeeper) | C30: =ViewProductDetail!A5 -> 4 | D30: =ViewProductDetail!C5 -> 0 | E30: =ViewProductDetail!F5 -> 0 | F30: =ViewProductDetail!L5 -> 3 | G30: =ViewProductDetail!M5 -> 1 | H30: =ViewProductDetail!N5 -> 0 | I30: =ViewProductDetail!O5 -> 4
A31: 20 | B31: View user list | C31: =ViewUserList!A5 -> 3 | D31: =ViewUserList!C5 -> 0 | E31: =ViewUserList!F5 -> 0 | F31: =ViewUserList!L5 -> 3 | G31: =ViewUserList!M5 -> 0 | H31: =ViewUserList!N5 -> 0 | I31: =ViewUserList!O5 -> 3
A32: 21 | B32: Activate/Deactivate account | C32: ='ActivateDeactivate account'!A5 -> 5 | D32: ='ActivateDeactivate account'!C5 -> 0 | E32: ='ActivateDeactivate account'!F5 -> 0 | F32: ='ActivateDeactivate account'!L5 -> 2 | G32: ='ActivateDeactivate account'!M5 -> 3 | H32: ='ActivateDeactivate account'!N5 -> 0 | I32: ='ActivateDeactivate account'!O5 -> 5
A33: 22 | B33: View Reports (Operator) | C33: ='View Reports (Operator)'!A5 -> 2 | D33: ='View Reports (Operator)'!C5 -> 0 | E33: ='View Reports (Operator)'!F5 -> 0 | F33: ='View Reports (Operator)'!L5 -> 2 | G33: ='View Reports (Operator)'!M5 -> 0 | H33: ='View Reports (Operator)'!N5 -> 0 | I33: ='View Reports (Operator)'!O5 -> 2
A34: 23 | B34: View Report Detail (Operator) | C34: ='View Report Detail (Operator)'!A5 -> 3 | D34: ='View Report Detail (Operator)'!C5 -> 0 | E34: ='View Report Detail (Operator)'!F5 -> 0 | F34: ='View Report Detail (Operator)'!L5 -> 3 | G34: ='View Report Detail (Operator)'!M5 -> 0 | H34: ='View Report Detail (Operator)'!N5 -> 0 | I34: ='View Report Detail (Operator)'!O5 -> 3
A35: 24 | B35: Activate/Deactivate Shop | C35: ='ActivateDeactivate Shop'!A5 -> 5 | D35: ='ActivateDeactivate Shop'!C5 -> 0 | E35: ='ActivateDeactivate Shop'!F5 -> 0 | F35: ='ActivateDeactivate Shop'!L5 -> 2 | G35: ='ActivateDeactivate Shop'!M5 -> 3 | H35: ='ActivateDeactivate Shop'!N5 -> 0 | I35: ='ActivateDeactivate Shop'!O5 -> 5
A36: 25 | B36: Activate/Deactivate Blog | C36: ='ActivateDeactivate Blog'!A5 -> 5 | D36: ='ActivateDeactivate Blog'!C5 -> 0 | E36: ='ActivateDeactivate Blog'!F5 -> 0 | F36: ='ActivateDeactivate Blog'!L5 -> 0 | G36: ='ActivateDeactivate Blog'!M5 -> 0 | H36: ='ActivateDeactivate Blog'!N5 -> 0 | I36: ='ActivateDeactivate Blog'!O5 -> 5
A37: 26 | B37: View Shop List (Operator) | C37: ='View Shop List (Operator)'!A5 -> 4 | D37: ='View Shop List (Operator)'!C5 -> 0 | E37: ='View Shop List (Operator)'!F5 -> 0 | F37: ='View Shop List (Operator)'!L5 -> 0 | G37: ='View Shop List (Operator)'!M5 -> 0 | H37: ='View Shop List (Operator)'!N5 -> 0 | I37: ='View Shop List (Operator)'!O5 -> 4
A38: 27 | B38: View Shop Detail (Operator) | C38: ='View Shop Detail (Operator)'!A5 -> 2 | D38: ='View Shop Detail (Operator)'!C5 -> 0 | E38: ='View Shop Detail (Operator)'!F5 -> 0 | F38: ='View Shop Detail (Operator)'!L5 -> 1 | G38: ='View Shop Detail (Operator)'!M5 -> 0 | H38: ='View Shop Detail (Operator)'!N5 -> 0 | I38: ='View Shop Detail (Operator)'!O5 -> 2
A39: 28 | B39: Add to Cart | C39: ='Add to Cart'!A5 -> 5 | D39: ='Add to Cart'!C5 -> 0 | E39: ='Add to Cart'!F5 -> 0 | F39: ='Add to Cart'!L5 -> 0 | G39: ='Add to Cart'!M5 -> 0 | H39: ='Add to Cart'!N5 -> 0 | I39: ='Add to Cart'!O5 -> 5
A40: 29 | B40: Remove from Cart | C40: ='Remove from Cart'!A5 -> 3 | D40: ='Remove from Cart'!C5 -> 0 | E40: ='Remove from Cart'!F5 -> 0 | F40: ='Remove from Cart'!L5 -> 3 | G40: ='Remove from Cart'!M5 -> 0 | H40: ='Remove from Cart'!N5 -> 0 | I40: ='Remove from Cart'!O5 -> 3
A41: 30 | B41: View Cart | C41: ='View Cart'!A5 -> 2 | D41: ='View Cart'!C5 -> 0 | E41: ='View Cart'!F5 -> 0 | F41: ='View Cart'!L5 -> 2 | G41: ='View Cart'!M5 -> 0 | H41: ='View Cart'!N5 -> 0 | I41: ='View Cart'!O5 -> 2
A42: 31 | B42: View Home Page | C42: ='View Home Page'!A5 -> 8 | D42: ='View Home Page'!C5 -> 0 | E42: ='View Home Page'!F5 -> 0 | F42: ='View Home Page'!L5 -> 8 | G42: ='View Home Page'!M5 -> 0 | H42: ='View Home Page'!N5 -> 0 | I42: ='View Home Page'!O5 -> 8
A43: 32 | B43: Filter Product by Category | C43: ='Filter Product by Category'!A5 -> 3 | D43: ='Filter Product by Category'!C5 -> 0 | E43: ='Filter Product by Category'!F5 -> 0 | F43: ='Filter Product by Category'!L5 -> 3 | G43: ='Filter Product by Category'!M5 -> 0 | H43: ='Filter Product by Category'!N5 -> 0 | I43: ='Filter Product by Category'!O5 -> 3
A44: 33 | B44: Get location from google Map | C44: ='Get location from google Map'!A5 -> 1 | D44: ='Get location from google Map'!C5 -> 0 | E44: ='Get location from google Map'!F5 -> 0 | F44: ='Get location from google Map'!L5 -> 1 | G44: ='Get location from google Map'!M5 -> 0 | H44: ='Get location from google Map'!N5 -> 0 | I44: ='Get location from google Map'!O5 -> 1
A45: 34 | B45: Auto count Rating for Shop | C45: ='Auto count Rating for Shop'!A5 -> 2 | D45: ='Auto count Rating for Shop'!C5 -> 0 | E45: ='Auto count Rating for Shop'!F5 -> 0 | F45: ='Auto count Rating for Shop'!L5 -> 2 | G45: ='Auto count Rating for Shop'!M5 -> 0 | H45: ='Auto count Rating for Shop'!N5 -> 0 | I45: ='Auto count Rating for Shop'!O5 -> 2
...

Sheet Register
A1: Code Module | C1: Register | F1: Method | L1: Register
A2: Created By | C2: AnhDQ | F2: Executed By | L2: AnhDQ
A3: Test requirement
A4: Passed | C4: Failed | F4: Untested | L4: N/A/B | O4: Total Test Cases
A5: =COUNTIF(F44:HQ44,"P") -> 18 | C5: =COUNTIF(F44:HQ44,"F") -> 0 | F5: =SUM(O5,-A5,-C5) -> 0 | L5: =COUNTIF(E43:HQ43,"N") -> 1 | M5: =COUNTIF(E43:HQ43,"A") -> 17 | N5: =COUNTIF(E43:HQ43,"B") -> 0 | O5: =COUNTA(E7:HT7) -> 18
F7: UTCID01 | G7: UTCID02 | H7: UTCID03 | I7: UTCID04 | J7: UTCID05 | K7: UTCID06 | L7: UTCID07 | M7: UTCID08 | N7: UTCID09 | O7: UTCID10 | P7: UTCID11 | Q7: UTCID12 | R7: UTCID13 | S7: UTCID14 | T7: UTCID15 | U7: UTCID16 | V7: UTCID17 | W7: UTCID18
A8: Condition | B8: Precondition
D9: Format password, email, phone number when entering
D10: Trong db có tồn tại số điện thoại 0234789156 và email abc@gmail.com
D11: Định dạng mật khẩu:ít nhất 8 kí tự, gồm 1 chữ hoa, 1 chữ số, 1 kí tự đặc biệt
D12: Số điện thoại phải có 10 chữ số và bắt đầu với số 0
B13: Phone
D14: 01327312983123 | F14: O | G14: O | H14: O | I14: O | J14: O | K14: O
D15: 0586619797 | L15: O | M15: O | N15: O | O15: O | P15: O | Q15: O
D16: 0234789156 | R16: O | S16: O | T16: O | U16: O | V16: O | W16: O
B17: Email
D18: abc@gmail.com | F18: O | I18: O | L18: O | O18: O | R18: O | U18: O
D19: ádasda | G19: O | J19: O | M19: O | P19: O | S19: O | V19: O
D20: anhdqhe170071@gmail.com | H20: O | K20: O | N20: O | Q20: O | T20: O | W20: O
B21: Password
D22: 123456 | F22: O | G22: O | H22: O | L22: O | M22: O | N22: O | R22: O | S22: O | T22: O
D23: Abc1234@ | I23: O | J23: O | K23: O | O23: O | P23: O | Q23: O | U23: O | V23: O | W23: O
A31: Confirm | B31: Return
D32: Đăng kí thành công | Q32: O
D33: Hiển thị thông báo lỗi | F33: O | G33: O | H33: O | I33: O | J33: O | K33: O | L33: O | M33: O | N33: O | O33: O | P33: O | R33: O | S33: O | T33: O | U33: O | V33: O | W33: O
B35: Exception
B37: Log message
D38: Sai định dạng nhập vào | F38: O | G38: O | H38: O | I38: O | J38: O | K38: O | L38: O | M38: O | N38: O | P38: O | R38: O | S38: O | T38: O | U38: O | V38: O
D39: Số điện thoại đã tồn tại | R39: O | S39: O | T39: O | U39: O | V39: O | W39: O
D40: Email đã tồn tại | F40: O | I40: O | L40: O | O40: O | R40: O | U40: O
D41: Đăng kí thành công | Q41: O
A43: Result | B43: Type(N : Normal, A : Abnormal, B : Boundary) | F43: A | G43: A | H43: A | I43: A | J43: A | K43: A | L43: A | M43: A | N43: A | O43: A | P43: A | Q43: N | R43: A | S43: A | T43: A | U43: A | V43: A | W43: A
B44: Passed/Failed | F44: P | G44: P | H44: P | I44: P | J44: P | K44: P | L44: P | M44: P | N44: P | O44: P | P44: P | Q44: P | R44: P | S44: P | T44: P | U44: P | V44: P | W44: P
B45: Executed Date | F45: 45724 | G45: 45724 | H45: 45724 | I45: 45724 | J45: 45724 | K45: 45724 | L45: 45724 | M45: 45724 | N45: 45724 | O45: 45724 | P45: 45724 | Q45: 45724 | R45: 45724 | S45: 45724 | T45: 45724 | U45: 45724 | V45: 45724 | W45: 45724
B46: Defect ID

Sheet AddBlog
A1: Code Module | C1: Blog Management | F1: Method | L1: AddBlogPost
A2: Created By | C2: AnhDQ | F2: Executed By | L2: AnhDQ
A3: Test requirement
A4: Passed | C4: Failed | F4: Untested | L4: N/A/B | O4: Total Test Cases
A5: =COUNTIF(F44:HQ44,"P") -> 3 | C5: =COUNTIF(F45:HQ45,"F") -> 0 | F5: =SUM(O5,-A5,-C5) -> 0 | L5: =COUNTIF(E43:HQ43,"N") -> 2 | M5: =COUNTIF(E43:HQ43,"A") -> 1 | N5: =COUNTIF(E43:HQ43,"B") -> 0 | O5: =COUNTA(E7:HT7) -> 3
F7: UTCID01 | G7: UTCID02 | H7: UTCID03
A8: Condition | B8: Precondition
D9: Logged into the system
B12: Content
D13: null | F13: O | H13: O
D14: "Cửa hàng này bán bún rất ngon" | G14: O
B15: Image
D16: null | F16: O | G16: O
D17: img1.jpg | H17: O
A31: Confirm | B31: Return
D32: Đăng bài thành công | G32: O | H32: O
D33: Lỗi khi đăng bài | F33: O
B38: Exception
B40: Log message
D41: Không thể bỏ trống cả nội dung và ảnh | F41: O
D42: Đăng bài thành công | G42: O | H42: O
A43: Result | B43: Type(N : Normal, A : Abnormal, B : Boundary) | F43: A | G43: N | H43: N
B44: Passed/Failed | F44: P | G44: P | H44: P
B45: Executed Date | F45: 45724 | G45: 45724 | H45: 45724
B46: Defect ID

Sheet Login
A1: Code Module | C1: Account Management | F1: Method | L1: Login
A2: Created By | C2: AnhDQ | F2: Executed By | L2: AnhDQ
A3: Test requirement
A4: Passed | C4: Failed | F4: Untested | L4: N/A/B | O4: Total Test Cases
A5: =COUNTIF(F39:HQ39,"P") -> 4 | C5: =COUNTIF(F39:HQ39,"F") -> 0 | F5: =SUM(O5,-A5,-C5) -> 0 | L5: =COUNTIF(E38:HQ38,"N") -> 1 | M5: =COUNTIF(E38:HQ38,"A") -> 3 | N5: =COUNTIF(E38:HQ38,"B") -> 0 | O5: =COUNTA(E7:HT7) -> 4
F7: UTCID01 | G7: UTCID02 | H7: UTCID03 | I7: UTCID04
A8: Condition | B8: Precondition
B9: Already have an account in the system database
D11: Phone:0586619796
D12: Password:Abc1234@
B13: Phone number
D14: 0586619796 | F14: O | H14: O
D15: 0123456789 | G15: O | I15: O
B16: Password
D17: Abc1234@ | F17: O | G17: O | W17: O
D18: 123456 | H18: O | I18: O
A27: Confirm | B27: Return
D28: Chuỗi JWT | F28: O
D29: Thông báo lỗi | G29: O | H29: O | I29: O
B33: Exception
B35: Log message
D36: Đăng nhập thành công
D37: Bad Credential
A38: Result | B38: Type(N : Normal, A : Abnormal, B : Boundary) | F38: N | G38: A | H38: A | I38: A
B39: Passed/Failed | F39: P | G39: P | H39: P | I39: P
B40: Executed Date | F40: 45724 | G40: 45724 | H40: 45724 | I40: 45724 | J40: 45724 | K40: 45724 | L40: 45724 | M40: 45724 | N40: 45724 | O40: 45724 | P40: 45724 | Q40: 45724 | R40: 45724 | S40: 45724 | T40: 45724
B41: Defect ID

Sheet Logout
A1: Code Module | C1: Account Management | F1: Method | L1: Logout
A2: Created By | C2: AnhDQ | F2: Executed By | L2: AnhDQ
A3: Test requirement
A4: Passed | C4: Failed | F4: Untested | L4: N/A/B | O4: Total Test Cases
A5: =COUNTIF(F39:HQ39,"P") -> 1 | C5: =COUNTIF(F39:HQ39,"F") -> 0 | F5: =SUM(O5,-A5,-C5) -> 0 | L5: =COUNTIF(E38:HQ38,"N") -> 1 | M5: =COUNTIF(E38:HQ38,"A") -> 0 | N5: =COUNTIF(E38:HQ38,"B") -> 0 | O5: =COUNTA(E7:HT7) -> 1
F7: UTCID01
A8: Condition | B8: Precondition
D9: Logged into the system
D10: Can connect with server
B13: Action
D14: Người dùng ấn vào đăng xuất | F14: O
A30: Confirm | B30: Return
D31: Chuyển về màn đăng nhập | F31: O
B33: Exception
B35: Log message
D36: Đăng xuất thành công
A38: Result | B38: Type(N : Normal, A : Abnormal, B : Boundary) | F38: N
B39: Passed/Failed | F39: P
B40: Executed Date | F40: 45724
B41: Defect ID

Sheet ViewProfile
A1: Code Module | C1: Account Management | F1: Method | L1: View profile
A2: Created By | C2: AnhDQ | F2: Executed By | L2: AnhDQ
A3: Test requirement | C3: <Brief description about requirements which are tested in this function>
A4: Passed | C4: Failed | F4: Untested | L4: N/A/B | O4: Total Test Cases
A5: =COUNTIF(F40:HQ40,"P") -> 2 | C5: =COUNTIF(F41:HQ41,"F") -> 0 | F5: =SUM(O5,-A5,-C5) -> 0 | L5: =COUNTIF(E39:HQ39,"N") -> 1 | M5: =COUNTIF(E39:HQ39,"A") -> 1 | N5: =COUNTIF(E39:HQ39,"B") -> 0 | O5: =COUNTA(E7:HT7) -> 2
F7: UTCID01 | G7: UTCID02
A8: Condition | B8: Precondition
D9: Logged into the system
B12: UserId
D13: 1 | F13: O
D14: null | G14: O
A29: Confirm | B29: Return
D30: View Profile | F30: O
D31: Lỗi khi view Profile | G31: O
B32: Exception
B34: Log message
D35: User Not Found | G35: O
A39: Result | B39: Type(N : Normal, A : Abnormal, B : Boundary) | F39: N | G39: A
B40: Passed/Failed | F40: P | G40: P
B41: Executed Date | F41: 45724 | G41: 45724 | H41: 45724 | I41: 45724 | J41: 45724 | K41: 45724 | L41: 45724
B42: Defect ID

Sheet EditProfile
A1: Code Module | C1: Account Management | F1: Method | L1: EditProfile
A2: Created By | C2: AnhDQ | F2: Executed By | L2: AnhDQ
A3: Test requirement
A4: Passed | C4: Failed | F4: Untested | L4: N/A/B | O4: Total Test Cases
A5: =COUNTIF(F45:HQ45,"P") -> 6 | C5: =COUNTIF(F46:HQ46,"F") -> 0 | F5: =SUM(O5,-A5,-C5) -> 0 | L5: =COUNTIF(E44:HQ44,"N") -> 1 | M5: =COUNTIF(E44:HQ44,"A") -> 5 | N5: =COUNTIF(E45:HQ45,"B") -> 0 | O5: =COUNTA(E7:HT7) -> 6
F7: UTCID01 | G7: UTCID02 | H7: UTCID03 | I7: UTCID04 | J7: UTCID05 | K7: UTCID06
A8: Condition | B8: Precondition
D9: Logged into the system
D10: Valid userId:1,profileId:1
B12: UserId
D13: 1 | K13: O
D14: null | F14: O
B15: ProfileId
D16: 1 | K16: O
D17: null | G17: O
B18: Gender
D19: Male | K19: O
D20: null | J20: O
B21: Email
D22: abc | H22: O
D23: anhdqhe170071@gmail.com | K23: O
B24: Dob
D25: 45767 | I25: O
D26: 37700 | K26: O
A33: Confirm | B33: Return
D34: Success | K34: O
D35: Fail | F35: O | G35: O | H35: O | I35: O | J35: O
B36: Exception
B38: Log message
D39: Chỉnh sửa thành công | K39: O
D40: Lỗi khi đọc profile | F40: O | G40: O
D41: Gender không hợp lệ | J41: O
D42: Email không hợp lệ | H42: O
D43: Ngày sinh không hợp lệ | I43: O
A44: Result | B44: Type(N : Normal, A : Abnormal, B : Boundary) | F44: A | G44: A | H44: A | I44: A | J44: A | K44: N
B45: Passed/Failed | F45: P | G45: P | H45: P | I45: P | J45: P | K45: P
B46: Executed Date | F46: 45724 | G46: 45724 | H46: 45724 | I46: 45724 | J46: 45724 | K46: 45724
B47: Defect ID

Sheet ChangePassword
A1: Code Module | C1: Account Management | F1: Method | L1: ChangePassword
A2: Created By | C2: AnhDQ | F2: Executed By | L2: AnhDQ
A3: Test requirement
A4: Passed | C4: Failed | F4: Untested | L4: N/A/B | O4: Total Test Cases
A5: =COUNTIF(F33:HQ33,"P") -> 4 | C5: =COUNTIF(F34:HQ34,"F") -> 0 | F5: =SUM(O5,-A5,-C5) -> 0 | L5: =COUNTIF(E32:HQ32,"N") -> 1 | M5: =COUNTIF(E32:HQ32,"A") -> 3 | N5: =COUNTIF(E33:HQ33,"B") -> 0 | O5: =COUNTA(E7:HT7) -> 4
F7: UTCID01 | G7: UTCID02 | H7: UTCID03 | I7: UTCID04
A8: Condition | B8: Precondition
D9: Logged into the system
D10: Current password:Abc1234@
B11: Old Password
D12: Abc1234@ | I12: O
D13: 12345678 | F13: O
B14: New Password
D15: 123456 | G15: O
D16: CDE1234@ | H16: O | I16: O
B17: Confirm password
D18: CDE1234@ | I18: O
D19: 123214 | G19: O | H19: O
A21: Confirm | B21: Return
D22: Đổi mật khẩu thành công
D23: Hiển thị thông báo lỗi | F23: O
B25: Exception
B27: Log message
D28: Mật khẩu mới không đúng định dạng | G28: O
D29: Mật khẩu không trùng | H29: O
D30: Đổi mật khẩu thành công | I30: O
D31: Sai mật khẩu cũ | F31: O
A32: Result | B32: Type(N : Normal, A : Abnormal, B : Boundary) | F32: A | G32: A | H32: A | I32: N
B33: Passed/Failed | F33: P | G33: P | H33: P | I33: P
B34: Executed Date | F34: 45724 | G34: 45724 | H34: 45724 | I34: 45724
B35: Defect ID

Sheet Forgotpassword
A1: Code Module | C1: Account Management | F1: Method | L1: ForgotPassword
A2: Created By | C2: AnhDQ | F2: Executed By | L2: AnhDQ
A3: Test requirement
A4: Passed | C4: Failed | F4: Untested | L4: N/A/B | O4: Total Test Cases
A5: =COUNTIF(F37:HT37,"P") -> 4 | C5: =COUNTIF(F38:HT38,"F") -> 0 | F5: =SUM(O5,-A5,-C5) -> 0 | L5: =COUNTIF(E36:HT36,"N") -> 1 | M5: =COUNTIF(E36:HT36,"A") -> 3 | N5: =COUNTIF(E37:HT37,"B") -> 0 | O5: =COUNTA(E7:HW7) -> 4
F7: UTCID01 | G7: UTCID02 | H7: UTCID03 | I7: UTCID04
A8: Condition | B8: Precondition
D9: Account must be registered with phone number in db
D10: Vào app nhưng chưa đăng nhập
D11: Mã OTP gửi về là 456789
D12: Định dạng mk :>=8 ký tự, phải chứa chữ hoa, số, kí tự đặc biệt
B13: Phone number
D14: 01234567896 | F14: O
D15: 0586619796 | G15: O | H15: O | I15: O
B16: New Password
D17: 123456 | G17: O
D18: CDE1234@ | H18: O | I18: O
B19: Confirm password
D20: CDE1234@ | G20: O | I20: O
D21: 123214 | H21: O
A26: Confirm | B26: Return
D27: Đổi mật khẩu thành công | I27: O
D28: Đổi mật khẩu thất bại | F28: O | G28: O | H28: O
B29: Exception
B31: Log message
D32: Mật khẩu mới không đúng định dạng | G32: O
D33: Mật khẩu không trùng | H33: O
D34: Không tìm thấy tài khoản | F34: O
D35: Đổi mật khẩu thành công | I35: O
A36: Result | B36: Type(N : Normal, A : Abnormal, B : Boundary) | F36: A | G36: A | H36: A | I36: N
B37: Passed/Failed | F37: P | G37: P | H37: P | I37: P
B38: Executed Date | F38: 45724 | G38: 45724 | H38: 45724 | I38: 45724
B39: Defect ID

Sheet ViewBlogList
A1: Code Module | C1: Blog Management | F1: Method | L1: View Blog List
A2: Created By | C2: AnhDQ | F2: Executed By | L2: AnhDQ
A3: Test requirement
A4: Passed | C4: Failed | F4: Untested | L4: N/A/B | O4: Total Test Cases
A5: =COUNTIF(F45:HQ45,"P") -> 2 | C5: =COUNTIF(F46:HQ46,"F") -> 0 | F5: =SUM(O5,-A5,-C5) -> 0 | L5: =COUNTIF(E44:HQ44,"N") -> 2 | M5: =COUNTIF(E45:HQ45,"A") -> 0 | N5: =COUNTIF(E45:HQ45,"B") -> 0 | O5: =COUNTA(E7:HT7) -> 2
F7: UTCID01 | G7: UTCID02
A8: Condition | B8: Precondition
D9: Logged into the system
D10: Đã đăng nhập thành công
D11: Không có Blog trong db | F11: O
D12: Có blog trong db | G12: O
A32: Confirm | B32: Return
D33: Danh sách các Blog có trên App | G33: O
D34: Null | F34: O
B39: Exception
B41: Log message
A44: Result | B44: Type(N : Normal, A : Abnormal, B : Boundary) | F44: N | G44: N
B45: Passed/Failed | F45: P | G45: P
B46: Executed Date | F46: 45724 | G46: 45724
B47: Defect ID

Sheet ViewBlogDetail
A1: Code Module | C1: Blog Management | F1: Method | L1: View Blog Detail
A2: Created By | C2: AnhDQ | F2: Executed By | L2: AnhDQ
A3: Test requirement
A4: Passed | C4: Failed | F4: Untested | L4: N/A/B | O4: Total Test Cases
A5: =COUNTIF(F45:HQ45,"P") -> 2 | C5: =COUNTIF(F46:HQ46,"F") -> 0 | F5: =SUM(O5,-A5,-C5) -> 0 | L5: =COUNTIF(E44:HQ44,"N") -> 1 | M5: =COUNTIF(E44:HQ44,"A") -> 1 | N5: =COUNTIF(E45:HQ45,"B") -> 0 | O5: =COUNTA(E7:HT7) -> 2
F7: UTCID01 | G7: UTCID02
A8: Condition | B8: Precondition
D9: Logged into the system
D10: Đã đăng nhập thành công
D11: Không có Blog trong db | F11: O
D12: Có blog trong db | G12: O
A32: Confirm | B32: Return
D33: BlogDetail | G33: O
D34: Không tìm thấy blog | F34: O
B39: Exception
B41: Log message
F42: O
A44: Result | B44: Type(N : Normal, A : Abnormal, B : Boundary) | F44: A | G44: N
B45: Passed/Failed | F45: P | G45: P
B46: Executed Date | F46: 45724 | G46: 45724
B47: Defect ID

Sheet EditBlog
A1: Code Module | C1: Blog Management | F1: Method | L1: EditBlog
A2: Created By | C2: AnhDQ | F2: Executed By | L2: AnhDQ
A3: Test requirement
A4: Passed | C4: Failed | F4: Untested | L4: N/A/B | O4: Total Test Cases
A5: =COUNTIF(F44:HQ44,"P") -> 4 | C5: =COUNTIF(F45:HQ45,"F") -> 0 | F5: =SUM(O5,-A5,-C5) -> 0 | L5: =COUNTIF(E43:HQ43,"N") -> 4 | M5: =COUNTIF(E44:HQ44,"A") -> 0 | N5: =COUNTIF(E44:HQ44,"B") -> 0 | O5: =COUNTA(E7:HT7) -> 4
F7: UTCID01 | G7: UTCID02 | H7: UTCID03 | I7: UTCID04
A8: Condition | B8: Precondition
D9: Logged in to the system, is the owner of at least 1 blog
B13: Content
D14: null | F14: O | G14: O
D15: "Cửa hàng này bán bún rất ngon" | H15: O | I15: O
B16: Image
D17: Không thêm ảnh mới | F17: O | H17: O
D18: img1.jpg | G18: O | I18: O
A31: Confirm | B31: Return
D32: Chỉnh sửa bài viết thành công | F32: O | G32: O | H32: O | I32: O
D33: Lỗi khi chỉnh sửa bài
B38: Exception
B40: Log message
D41: Chỉnh sửa bài thành công
A43: Result | B43: Type(N : Normal, A : Abnormal, B : Boundary) | F43: N | G43: N | H43: N | I43: N
B44: Passed/Failed | F44: P | G44: P | H44: P | I44: P
B45: Executed Date | F45: 45724 | G45: 45724 | H45: 45724 | I45: 45724
B46: Defect ID

Sheet CommentReplyonBlog
A1: Code Modulenưa | C1: Blog Management | F1: Method | L1: Comment/Reply on Blog
A2: Created By | C2: AnhDQ | F2: Executed By | L2: NguyenT
A3: Test requirement
A4: Passed | C4: Failed | F4: Untested | L4: N/A/B | O4: Total Test Cases
A5: =COUNTIF(F42:HQ42,"P") -> 8 | C5: =COUNTIF(F42:HQ42,"F") -> 0 | F5: =SUM(O5,-A5,-C5) -> 0 | L5: =COUNTIF(E41:HQ41,"N") -> 2 | M5: =COUNTIF(E41:HQ41,"A") -> 4 | N5: =COUNTIF(E41:HQ41,"B") -> 2 | O5: =COUNTA(E7:HT7) -> 8
F7: UTCID01 | G7: UTCID02 | H7: UTCID03 | I7: UTCID04 | J7: UTCID05 | K7: UTCID06 | L7: UTCID07 | M7: UTCID08
A8: Condition | B8: Precondition
D9: Logged into the system
B11: BlogId
D12: 1 | F12: O | H12: O | I12: O | J12: O | K12: O | L12: O | M12: O
D13: null | G13: O
B14: UserId
D15: 1 | F15: O | G15: O | H15: O | I15: O | K15: O | L15: O | M15: O
D16: null | J16: O
B17: ParentId
D18: 2 | H18: O | I18: O
D19: null | F19: O | G19: O | J19: O | K19: O | L19: O | M19: O
B20: IsReply
D21: TRUE | H21: O | I21: O | K21: O
D22: FALSE | F22: O | G22: O | J22: O | L22: O | M22: O
B23: Parent blogId
D24: 1 | H24: O
D25: 2 | I25: O
D26: null | F26: O | G26: O | J26: O | K26: O | L26: O | M26: O
B27: content
D28: "" | L28: O
D29: null | M29: O
D30: "comment content" | F30: O | G30: O | H30: O | I30: O | J30: O | K30: O
A32: Confirm | B32: Return
D33: TRUE | F33: O | H33: O
D34: FALSE | G34: O | I34: O | J34: O | K34: O | L34: O | M34: O
B35: Exception
D36: NotFoundException | G36: O | J36: O
D37: BadRequestException | I37: O | K37: O | L37: O | M37: O
B38: Log message
A41: Result | B41: Type(N : Normal, A : Abnormal, B : Boundary) | F41: N | G41: A | H41: N | I41: A | J41: A | K41: A | L41: B | M41: B
B42: Passed/Failed | F42: P | G42: P | H42: P | I42: P | J42: P | K42: P | L42: P | M42: P
B43: Executed Date | F43: 45724 | G43: 45724 | H43: 45724 | I43: 45724 | J43: 45724 | K43: 45724 | L43: 45724 | M43: 45724
B44: Defect ID

Sheet DeleteBlog
A1: Code Module | C1: Blog Management | F1: Method | L1: Delete Blog Post
A2: Created By | C2: AnhDQ | F2: Executed By | L2: AnhDQ
A3: Test requirement
A4: Passed | C4: Failed | F4: Untested | L4: N/A/B | O4: Total Test Cases
A5: =COUNTIF(F45:HQ45,"P") -> 1 | C5: =COUNTIF(F46:HQ46,"F") -> 0 | F5: =SUM(O5,-A5,-C5) -> 0 | L5: =COUNTIF(E44:HQ44,"N") -> 1 | M5: =COUNTIF(E44:HQ44,"A") -> 0 | N5: =COUNTIF(E44:HQ44,"B") -> 0 | O5: =COUNTA(E7:HT7) -> 1
F7: UTCID01
A8: Condition | B8: Precondition
D9: Logged in to the system, is the owner of at least 1 blog
D10: Đã đăng nhập vào hệ thống
D11: Sở hữu ít nhất 1 bài viết | F11: O
B13: Action
D14: Người dùng ấn vào xóa bài viết | F14: O
A32: Confirm | B32: Return
D33: T | F33: O
D34: F
B39: Exception
B41: Log message
D42: Xóa bài viết thành công
A44: Result | B44: Type(N : Normal, A : Abnormal, B : Boundary) | F44: N
B45: Passed/Failed | F45: P
B46: Executed Date | F46: 45724
B47: Defect ID

Sheet ViewShopProduct
A1: Code Module | C1: Product Management | F1: Method | L1: View Shop Product
A2: Created By | C2: AnhDQ | F2: Executed By | L2: AnhDQ
A3: Test requirement
A4: Passed | C4: Failed | F4: Untested | L4: N/A/B | O4: Total Test Cases
A5: =COUNTIF(F39:HQ39,"P") -> 5 | C5: =COUNTIF(F39:HQ39,"F") -> 0 | F5: =SUM(O5,-A5,-C5) -> 0 | L5: =COUNTIF(E38:HQ38,"N") -> 5 | M5: =COUNTIF(E38:HQ38,"A") -> 0 | N5: =COUNTIF(E38:HQ38,"B") -> 0 | O5: =COUNTA(E7:HT7) -> 5
F7: UTCID01 | G7: UTCID02 | H7: UTCID03 | I7: UTCID04 | J7: UTCID05
A8: Condition | B8: Precondition
D9: Logged into the system, is the owner of the shop
D10: Can connect with server
B15: FoodOption
D16: typeId:1,price:10.000 | F16: O | G16: O | J16: O
D17: typeId:2,price:50.000 | F17: O | H17: O | I17: O | J17: O
B19: Discount
D20: null | J20: O
D21: 0,1 | F21: O | G21: O | H21: O
D22: 1 | I22: O
A29: Confirm | B29: Return
D30: TRUE | F30: O | G30: O | H30: O | I30: O | J30: O
D31: Fasle
B32: Exception
B34: Log message
D35: Giá sản phẩm :0 | F35: O | G35: O | I35: O
D36: Giá sản phẩm :45.000 | H36: O
D37: Giá sản phẩm :50.000 | J37: O
A38: Result | B38: Type(N : Normal, A : Abnormal, B : Boundary) | F38: N | G38: N | H38: N | I38: N | J38: N
B39: Passed/Failed | F39: P | G39: P | H39: P | I39: P | J39: P
B40: Executed Date | F40: 45724 | G40: 45724 | H40: 45724 | I40: 45724 | J40: 45724
B41: Defect ID

Sheet ViewProductDetail
A1: Code Module | C1: Product Management | F1: Method | L1: View Product Detail
A2: Created By | C2: AnhDQ | F2: Executed By | L2: AnhDQ
A3: Test requirement
A4: Passed | C4: Failed | F4: Untested | L4: N/A/B | O4: Total Test Cases
A5: =COUNTIF(F39:HQ39,"P") -> 4 | C5: =COUNTIF(F39:HQ39,"F") -> 0 | F5: =SUM(O5,-A5,-C5) -> 0 | L5: =COUNTIF(E38:HQ38,"N") -> 3 | M5: =COUNTIF(E38:HQ38,"A") -> 1 | N5: =COUNTIF(E38:HQ38,"B") -> 0 | O5: =COUNTA(E7:HT7) -> 4
F7: UTCID01 | G7: UTCID02 | H7: UTCID03 | I7: UTCID04
A8: Condition | B8: Precondition
D9: Logged in to the system, is the owner of the shop, has at least 1 product
D10: Can connect with server
B13: FoodOption
D14: typeId:1,price:10.000 | F14: O | G14: O
D15: typeId:2,price:50.000 | G15: O | H15: O | I15: O
B17: Discount
D18: null | F18: O | G18: O
D19: 0,1 | F19: O | H19: O
D20: 1 | F20: O | I20: O
A29: Confirm | B29: Return
D30: T | F30: O | G30: O | H30: O | I30: O
D31: F
B32: Exception
B34: Log message
D35: Giá sản phẩm :0 | F35: O | I35: O
D36: Giá sản phẩm :45.000 | H36: O
D37: Giá sản phẩm :50.000 | G37: O
A38: Result | B38: Type(N : Normal, A : Abnormal, B : Boundary) | F38: A | G38: N | H38: N | I38: N
B39: Passed/Failed | F39: P | G39: P | H39: P | I39: P
B40: Executed Date | F40: 45724 | G40: 45724 | H40: 45724 | I40: 45724
B41: Defect ID

Sheet ViewProductList
A1: Code Module | C1: Product Management | F1: Method | L1: View Product List
A2: Created By | C2: AnhDQ | F2: Executed By | L2: AnhDQ
A3: Test requirement
A4: Passed | C4: Failed | F4: Untested | L4: N/A/B | O4: Total Test Cases
A5: =COUNTIF(F39:HQ39,"P") -> 4 | C5: =COUNTIF(F39:HQ39,"F") -> 0 | F5: =SUM(O5,-A5,-C5) -> 0 | L5: =COUNTIF(E38:HQ38,"N") -> 3 | M5: =COUNTIF(E38:HQ38,"A") -> 1 | N5: =COUNTIF(E38:HQ38,"B") -> 0 | O5: =COUNTA(E7:HT7) -> 4
F7: UTCID01 | G7: UTCID02 | H7: UTCID03 | I7: UTCID04
A8: Condition | B8: Precondition
D9: Logged into the system, use the search section to filter out a list of products, there must be at least 1 product in the database
D10: Can connect with server
B13: Search
D14: null | F14: O
D15: Cơm rang gà | G15: O | H15: O | I15: O
B16: FoodOption
D17: typeId:1,price:10.000 | G17: O
D18: typeId:2,price:50.000 | G18: O | H18: O | I18: O
B19: Discount
D20: null | G20: O
D21: 0,1 | H21: O
D22: 1 | I22: O
A29: Confirm | B29: Return
D30: T | F30: O | G30: O | H30: O | I30: O
D31: F
B32: Exception
B34: Log message
D35: Giá sản phẩm :0 | I35: O
D36: Giá sản phẩm :45.000 | H36: O
D37: Giá sản phẩm :50.000 | G37: O
A38: Result | B38: Type(N : Normal, A : Abnormal, B : Boundary) | F38: A | G38: N | H38: N | I38: N
B39: Passed/Failed | F39: P | G39: P | H39: P | I39: P
B40: Executed Date | F40: 45724 | G40: 45724 | H40: 45724 | I40: 45724
B41: Defect ID

Sheet AddProduct
A1: Code Module | C1: Product Management | F1: Method | L1: Add Product
A2: Created By | C2: AnhDQ | F2: Executed By | L2: AnhDQ
A3: Test requirement
A4: Passed | C4: Failed | F4: Untested | L4: N/A/B | O4: Total Test Cases
A5: =COUNTIF(F45:HQ45,"P") -> 6 | C5: =COUNTIF(F45:HQ45,"F") -> 0 | F5: =SUM(O5,-A5,-C5) -> 0 | L5: =COUNTIF(E44:HQ44,"N") -> 1 | M5: =COUNTIF(E44:HQ44,"A") -> 3 | N5: =COUNTIF(E44:HQ44,"B") -> 2 | O5: =COUNTA(E7:HT7) -> 6
F7: UTCID01 | G7: UTCID02 | H7: UTCID03 | I7: UTCID04 | J7: UTCID05 | K7: UTCID06
A8: Condition | B8: Precondition
D9: Logged into the system, is the owner of the shop
D10: Can connect with server
B15: Name
D16: Cơm rang | K16: O
D17: null | F17: O
B18: Category
D19: null | G19: O
D20: Cơm | K20: O
B21: FoodOption
D22: null | H22: O
D23: typeId:2,price:50.000 | K23: O
B24: Expiry Date
D25: 40288 | I25: O
D26: 45736 | K26: O
B27: Quantity
D28: 0 | J28: O
D29: 1 | K29: O
A34: Confirm | B34: Return
D35: T | K35: O
D36: F | F36: O | G36: O | H36: O | I36: O | J36: O
B37: Exception
B39: Log message
D40: Không thể bỏ trống các trường đánh dấu * | F40: O | G40: O | H40: O
D41: Ngày hết hạn không thể trong quá khứ | I41: O
D42: Số lương phải lớn hơn 0 | J42: O
D43: Thêm sản phẩm thành công | K43: O
A44: Result | B44: Type(N : Normal, A : Abnormal, B : Boundary) | F44: A | G44: A | H44: A | I44: B | J44: B | K44: N
B45: Passed/Failed | F45: P | G45: P | H45: P | I45: P | J45: P | K45: P
B46: Executed Date | F46: 45724 | G46: 45724 | H46: 45724 | I46: 45724 | J46: 45724 | K46: 45724
B47: Defect ID

Sheet EditProduct
A1: Code Module | C1: Product Management | F1: Method | L1: EditProduct
A2: Created By | C2: AnhDQ | F2: Executed By | L2: AnhDQ
A3: Test requirement
A4: Passed | C4: Failed | F4: Untested | L4: N/A/B | O4: Total Test Cases
A5: =COUNTIF(F45:HQ45,"P") -> 6 | C5: =COUNTIF(F45:HQ45,"F") -> 0 | F5: =SUM(O5,-A5,-C5) -> 0 | L5: =COUNTIF(E44:HQ44,"N") -> 1 | M5: =COUNTIF(E44:HQ44,"A") -> 3 | N5: =COUNTIF(E44:HQ44,"B") -> 2 | O5: =COUNTA(E7:HT7) -> 6
F7: UTCID01 | G7: UTCID02 | H7: UTCID03 | I7: UTCID04 | J7: UTCID05 | K7: UTCID06
A8: Condition | B8: Precondition
D9: Logged in to the system, is the owner of the shop, has at least 1 product
D10: Can connect with server
B15: Name
D16: Cơm rang | K16: O
D17: null | F17: O
B18: Category
D19: null | G19: O
D20: Cơm | K20: O
B21: FoodOption
D22: null | H22: O
D23: typeId:2,price:50.000 | K23: O
B24: Expiry Date
D25: 40288 | I25: O
D26: 45736 | K26: O
B27: Quantity
D28: 0 | J28: O
D29: 1 | K29: O
A34: Confirm | B34: Return
D35: T | K35: O
D36: F | F36: O | G36: O | H36: O | I36: O | J36: O
B37: Exception
B39: Log message
D40: Không thể bỏ trống các trường đánh dấu * | F40: O | G40: O | H40: O
D41: Ngày hết hạn không thể trong quá khứ | I41: O
D42: Số lương phải lớn hơn 0 | J42: O
D43: Thêm sản phẩm thành công | K43: O
A44: Result | B44: Type(N : Normal, A : Abnormal, B : Boundary) | F44: A | G44: A | H44: A | I44: B | J44: B | K44: N
B45: Passed/Failed | F45: P | G45: P | H45: P | I45: P | J45: P | K45: P
B46: Executed Date | F46: 45724 | G46: 45724 | H46: 45724 | I46: 45724 | J46: 45724 | K46: 45724
B47: Defect ID

Sheet DeleteProduct
A1: Code Module | C1: Product Management | F1: Method | L1: Delete Product
A2: Created By | C2: AnhDQ | F2: Executed By | L2: AnhDQ
A3: Test requirement
A4: Passed | C4: Failed | F4: Untested | L4: N/A/B | O4: Total Test Cases
A5: =COUNTIF(F39:HQ39,"P") -> 1 | C5: =COUNTIF(F39:HQ39,"F") -> 0 | F5: =SUM(O5,-A5,-C5) -> 0 | L5: =COUNTIF(E38:HQ38,"N") -> 1 | M5: =COUNTIF(E38:HQ38,"A") -> 0 | N5: =COUNTIF(E38:HQ38,"B") -> 0 | O5: =COUNTA(E7:HT7) -> 1
F7: UTCID01
A8: Condition | B8: Precondition
D9: Logged in to the system, is the owner of the shop, has at least 1 product
D10: Can connect with server
B13: Action
D14: Ấn vào nút xóa sản phẩm | F14: O
A30: Confirm | B30: Return
D31: T | F31: O
D32: F
B33: Exception
B35: Log message
D36: "success"
D37: "input1 is null"
A38: Result | B38: Type(N : Normal, A : Abnormal, B : Boundary) | F38: N
B39: Passed/Failed | F39: P
B40: Executed Date | F40: 45724
B41: Defect ID

Sheet ViewUserList
A1: Code Module | C1: OperatorFeature | F1: Method | L1: View user list
A2: Created By | C2: AnhDQ | F2: Executed By | L2: AnhDQ
A3: Test requirement
A4: Passed | C4: Failed | F4: Untested | L4: N/A/B | O4: Total Test Cases
A5: =COUNTIF(F39:HQ39,"P") -> 3 | C5: =COUNTIF(F39:HQ39,"F") -> 0 | F5: =SUM(O5,-A5,-C5) -> 0 | L5: =COUNTIF(E38:HQ38,"N") -> 3 | M5: =COUNTIF(E38:HQ38,"A") -> 0 | N5: =COUNTIF(E38:HQ38,"B") -> 0 | O5: =COUNTA(E7:HT7) -> 3
F7: UTCID01 | G7: UTCID02 | H7: UTCID03
A8: Condition | B8: Precondition
D9: Logged into the system
D10: Can connect with server
D11: Danh sách người dùng trống | F11: O
D12: Danh sách người dùng có dữ liệu | G12: O | H12: O
B14: Search
D15: "John" | F15: O | G15: O
D16: "jasjkdnasjdnas" | H16: O
A30: Confirm | B30: Return
D31: T | F31: O | G31: O | H31: O
D32: F
B33: Exception
B35: Log message
D36: Null | F36: O | H36: O
D37: Danh sách người dùng | G37: O
A38: Result | B38: Type(N : Normal, A : Abnormal, B : Boundary) | F38: N | G38: N | H38: N
B39: Passed/Failed | F39: P | G39: P | H39: P
B40: Executed Date | F40: 45724 | G40: 45724 | H40: 45724
B41: Defect ID

Sheet ActivateDeactivate account
A1: Code Module | C1: Operator Feature | F1: Method | L1: Activate/Deactivate account
A2: Created By | C2: AnhDQ | F2: Executed By
A3: Test requirement | C3: Successfully change user status
A4: Passed | C4: Failed | F4: Untested | L4: N/A/B | O4: Total Test Cases
A5: =COUNTIF(F39:HQ39,"P") -> 5 | C5: =COUNTIF(F39:HQ39,"F") -> 0 | F5: =SUM(O5,-A5,-C5) -> 0 | L5: =COUNTIF(E38:HQ38,"N") -> 2 | M5: =COUNTIF(E38:HQ38,"A") -> 3 | N5: =COUNTIF(E38:HQ38,"B") -> 0 | O5: =COUNTA(E7:HT7) -> 5
F7: UTCID01 | G7: UTCID02 | H7: UTCID03 | I7: UTCID04 | J7: UTCID05
A8: Condition | B8: Precondition
D9: Can connect with server
D10: Exsited User:User 1:id=1,status=ACTIVE;User 2:id=2,status=INACTIVE
B12: UserId
D13: null | F13: O
D14: 1 | G14: O | H14: O
D15: 2 | I15: O | J15: O
B16: Status
D17: ACTIVE | G17: O | I17: O
D18: INACTIVE | H18: O | J18: O
A29: Confirm | B29: Return
D30: Success | H30: O | I30: O
D31: FALSE | F31: O | G31: O | J31: O
B32: Exception
B34: Log message
D35: User is already active/inactive | G35: O | J35: O
D36: User not found | F36: O
D37: Success | H37: O | I37: O
A38: Result | B38: Type(N : Normal, A : Abnormal, B : Boundary) | F38: A | G38: A | H38: N | I38: N | J38: A
B39: Passed/Failed | F39: P | G39: P | H39: P | I39: P | J39: P
B40: Executed Date | F40: 39139 | G40: 39139 | H40: 39140 | I40: 39141 | J40: 39142
B41: Defect ID

Sheet View Report Detail (Operator)
A1: Code Module | C1: Operator Feature | F1: Method | L1: View Report Detail (Operator)
A2: Created By | C2: AnhDQ | F2: Executed By
A3: Test requirement | C3: <Brief description about requirements which are tested in this function>
A4: Passed | C4: Failed | F4: Untested | L4: N/A/B | O4: Total Test Cases
A5: =COUNTIF(F38:HQ38,"P") -> 3 | C5: =COUNTIF(F38:HQ38,"F") -> 0 | F5: =SUM(O5,-A5,-C5) -> 0 | L5: =COUNTIF(E37:HQ37,"N") -> 3 | M5: =COUNTIF(E37:HQ37,"A") -> 0 | N5: =COUNTIF(E37:HQ37,"B") -> 0 | O5: =COUNTA(E7:HT7) -> 3
F7: UTCID01 | G7: UTCID02 | H7: UTCID03
A8: Condition | B8: Precondition
D9: Can connect with server
B13: Filter by Type
D14: BLOG | F14: O
D15: SHOP | G15: O
D16: PRODUCT | H16: O
A29: Confirm | B29: Return
D30: T | F30: O | G30: O | H30: O
D31: F
B32: Exception
B34: Log message
D35: "success" | F35: O | G35: O | H35: O
A37: Result | B37: Type(N : Normal, A : Abnormal, B : Boundary) | F37: N | G37: N | H37: N
B38: Passed/Failed | F38: P | G38: P | H38: P
B39: Executed Date | F39: 39139 | G39: 39139 | H39: 39140
B40: Defect ID

Sheet View Reports (Operator)
A1: Code Module | C1: Operator Feature | F1: Method | L1: View Reports (Operator)
A2: Created By | C2: AnhDQ | F2: Executed By
A3: Test requirement | C3: <Brief description about requirements which are tested in this function>
A4: Passed | C4: Failed | F4: Untested | L4: N/A/B | O4: Total Test Cases
A5: =COUNTIF(F38:HQ38,"P") -> 2 | C5: =COUNTIF(F38:HQ38,"F") -> 0 | F5: =SUM(O5,-A5,-C5) -> 0 | L5: =COUNTIF(E37:HQ37,"N") -> 2 | M5: =COUNTIF(E37:HQ37,"A") -> 0 | N5: =COUNTIF(E37:HQ37,"B") -> 0 | O5: =COUNTA(E7:HT7) -> 2
F7: UTCID01 | G7: UTCID02
A8: Condition | B8: Precondition
D9: Can connect with server
B11: Report
D12: null | F12: O
D13: Có dữ liệu | G13: O
W22: O
A29: Confirm | B29: Return
D30: T | F30: O | G30: O
D31: F
B32: Exception
B34: Log message
D35: "success" | F35: O | G35: O
A37: Result | B37: Type(N : Normal, A : Abnormal, B : Boundary) | F37: N | G37: N
B38: Passed/Failed | F38: P | G38: P
B39: Executed Date | F39: 39139 | G39: 39139
B40: Defect ID

Sheet ActivateDeactivate Shop
A1: Code Module | C1: Operator Feature | F1: Method | L1: Activate/Deactivate Shop
A2: Created By | C2: AnhDQ | F2: Executed By
A3: Test requirement | C3: <Brief description about requirements which are tested in this function>
A4: Passed | C4: Failed | F4: Untested | L4: N/A/B | O4: Total Test Cases
A5: =COUNTIF(F39:HQ39,"P") -> 5 | C5: =COUNTIF(F39:HQ39,"F") -> 0 | F5: =SUM(O5,-A5,-C5) -> 0 | L5: =COUNTIF(E38:HQ38,"N") -> 2 | M5: =COUNTIF(E38:HQ38,"A") -> 3 | N5: =COUNTIF(E38:HQ38,"B") -> 0 | O5: =COUNTA(E7:HT7) -> 5
F7: UTCID01 | G7: UTCID02 | H7: UTCID03 | I7: UTCID04 | J7: UTCID05
A8: Condition | B8: Precondition
D9: Can connect with server
D10: Exsited Shop:Shop 1:id=1,status=ACTIVE;Shop 2:id=2,status=INACTIVE
B12: ShopId
D13: null | F13: O
D14: 1 | G14: O | H14: O
D15: 2 | I15: O | J15: O
B16: Status
D17: ACTIVE | G17: O | I17: O
D18: INACTIVE | H18: O | J18: O
A29: Confirm | B29: Return
D30: Success | H30: O | I30: O
D31: FALSE | F31: O | G31: O | J31: O
B32: Exception
B34: Log message
D35: Shop is already active/inactive | G35: O | J35: O
D36: Shop not found | F36: O
D37: Success | H37: O | I37: O
A38: Result | B38: Type(N : Normal, A : Abnormal, B : Boundary) | F38: A | G38: A | H38: N | I38: N | J38: A
B39: Passed/Failed | F39: P | G39: P | H39: P | I39: P | J39: P
B40: Executed Date | F40: 39139 | G40: 39139 | H40: 39140 | I40: 39141 | J40: 39142
B41: Defect ID

Sheet ActivateDeactivate Blog
A1: Code Module | C1: Operator Feature | F1: Method | L1: Activate/Deactivate Blog
A2: Created By | C2: AnhDQ | F2: Executed By
A3: Test requirement | C3: <Brief description about requirements which are tested in this function>
A4: Passed | C4: Failed | F4: Untested | L4: N/A/B | O4: Total Test Cases
A5: =COUNTIF(F44:HQ44,"P") -> 5 | C5: =COUNTIF(F45:HQ45,"F") -> 0 | F5: =SUM(O5,-A5,-C5) -> 0 | L5: =COUNTIF(E44:HQ44,"N") -> 0 | M5: =COUNTIF(E44:HQ44,"A") -> 0 | N5: =COUNTIF(E44:HQ44,"B") -> 0 | O5: =COUNTA(E7:HT7) -> 5
F7: UTCID01 | G7: UTCID02 | H7: UTCID03 | I7: UTCID04 | J7: UTCID05
A8: Condition | B8: Precondition
D10: Exsited Blog:Blog 1:id=1,status=ACTIVE;Blog 2:id=2,status=INACTIVE
B12: BlogId
D13: null | F13: O
D14: 1 | G14: O | H14: O
D15: 2 | I15: O | J15: O
B16: Status
D17: ACTIVE | G17: O | I17: O
D18: INACTIVE | H18: O | J18: O
A31: Confirm | B31: Return
D32: Success | H32: O | I32: O
D33: FALSE | F33: O | G33: O | J33: O
B34: Exception
B36: Log message
D37: Blog is already active/inactive | G37: O | J37: O
D38: Blog not found | F38: O
D39: Success | H39: O | I39: O
A43: Result | B43: Type(N : Normal, A : Abnormal, B : Boundary) | F43: A | G43: A | H43: N | I43: N | J43: A
B44: Passed/Failed | F44: P | G44: P | H44: P | I44: P | J44: P
B45: Executed Date | F45: 39139 | G45: 39139 | H45: 39140 | I45: 39141 | J45: 39142
B46: Defect ID

Sheet View Shop List (Operator)
A1: Code Module | C1: Operator Feature | F1: Method | L1: methodName
A2: Created By | C2: AnhDQ | F2: Executed By
A3: Test requirement | C3: <Brief description about requirements which are tested in this function>
A4: Passed | C4: Failed | F4: Untested | L4: N/A/B | O4: Total Test Cases
A5: =COUNTIF(F44:HQ44,"P") -> 4 | C5: =COUNTIF(F45:HQ45,"F") -> 0 | F5: =SUM(O5,-A5,-C5) -> 0 | L5: =COUNTIF(E44:HQ44,"N") -> 0 | M5: =COUNTIF(E44:HQ44,"A") -> 0 | N5: =COUNTIF(E44:HQ44,"B") -> 0 | O5: =COUNTA(E7:HT7) -> 4
F7: UTCID01 | G7: UTCID02 | H7: UTCID03 | I7: UTCID04
A8: Condition | B8: Precondition
B13: Shop
D14: null | F14: O
D15: Not null | G15: O
B16: Filter
D17: ACTIVE | H17: O
D18: null | I18: O
A31: Confirm | B31: Return
D32: Danh sách Shop | G32: O | H32: O | I32: O
D33: Null | F33: O
B38: Exception
B40: Log message
A43: Result | B43: Type(N : Normal, A : Abnormal, B : Boundary) | F43: N | G43: N | H43: N | I43: N
B44: Passed/Failed | F44: P | G44: P | H44: P | I44: P
B45: Executed Date | F45: 39139 | G45: 39139 | H45: 39139 | I45: 39139
B46: Defect ID

Sheet View Shop Detail (Operator)
A1: Code Module | C1: Operator Feature | F1: Method | L1: View Shop Detail (Operator)
A2: Created By | C2: AnhDQ | F2: Executed By
A3: Test requirement | C3: <Brief description about requirements which are tested in this function>
A4: Passed | C4: Failed | F4: Untested | L4: N/A/B | O4: Total Test Cases
A5: =COUNTIF(F44:HQ44,"P") -> 2 | C5: =COUNTIF(F45:HQ45,"F") -> 0 | F5: =SUM(O5,-A5,-C5) -> 0 | L5: =COUNTIF(E43:HQ43,"N") -> 1 | M5: =COUNTIF(E44:HQ44,"A") -> 0 | N5: =COUNTIF(E44:HQ44,"B") -> 0 | O5: =COUNTA(E7:HT7) -> 2
F7: UTCID01 | G7: UTCID02
A8: Condition | B8: Precondition
B12: ShopId
D13: null | F13: O
D14: 1 | G14: O
A31: Confirm | B31: Return
D32: ShopDetail | G32: O
D33: null | F33: O
B38: Exception
B40: Log message
D41: Shop not Found | F41: O
D42: Success | G42: O
A43: Result | B43: Type(N : Normal, A : Abnormal, B : Boundary) | F43: A | G43: N
B44: Passed/Failed | F44: P | G44: P
B45: Executed Date | F45: 39139 | G45: 39139
B46: Defect ID

Sheet Auto count Rating for Shop
A1: Code Module | C1: Common Feature | F1: Method | L1: Auto count Rating for Shop
A2: Created By | C2: AnhDQ | F2: Executed By
A3: Test requirement | C3: <Brief description about requirements which are tested in this function>
A4: Passed | C4: Failed | F4: Untested | L4: N/A/B | O4: Total Test Cases
A5: =COUNTIF(F38:HQ38,"P") -> 2 | C5: =COUNTIF(F38:HQ38,"F") -> 0 | F5: =SUM(O5,-A5,-C5) -> 0 | L5: =COUNTIF(E37:HQ37,"N") -> 2 | M5: =COUNTIF(E37:HQ37,"A") -> 0 | N5: =COUNTIF(E37:HQ37,"B") -> 0 | O5: =COUNTA(E7:HT7) -> 2
F7: UTCID01 | G7: UTCID02
A8: Condition | B8: Precondition
D9: Can connect with server
D10: Shop with 4.0 rate, 10 view count
B12: Rate
D13: 0 | F13: O
D14: 5 | G14: O
A29: Confirm | B29: Return
D30: Rate:3.6 | F30: O
D31: Rate:4.1 | G31: O
B32: Exception
B34: Log message
A37: Result | B37: Type(N : Normal, A : Abnormal, B : Boundary) | F37: N | G37: N
B38: Passed/Failed | F38: P | G38: P
B39: Executed Date | F39: 39139 | G39: 39139
B40: Defect ID

Sheet Add to Cart
A1: Code Module | C1: Cart Management | F1: Method | L1: Add to Cart
A2: Created By | C2: AnhDQ | F2: Executed By
A3: Test requirement | C3: <Brief description about requirements which are tested in this function>
A4: Passed | C4: Failed | F4: Untested | L4: N/A/B | O4: Total Test Cases
A5: =COUNTIF(F51:HQ51,"P") -> 5 | C5: =COUNTIF(F52:HQ52,"F") -> 0 | F5: =SUM(O5,-A5,-C5) -> 0 | L5: =COUNTIF(E51:HQ51,"N") -> 0 | M5: =COUNTIF(E51:HQ51,"A") -> 0 | N5: =COUNTIF(E51:HQ51,"B") -> 0 | O5: =COUNTA(E7:HT7) -> 5
F7: UTCID01 | G7: UTCID02 | H7: UTCID03 | I7: UTCID04 | J7: UTCID05
A8: Condition | B8: Precondition
D10: An exsited cart with product id:1,quantity 1,FoodOption id 1,quantity :1
D11: Product 1 is from Shop 1,Product 2 is from Shop 2
B12: Product
D13: null | F13: O
D14: 1 | G14: O | H14: O | I14: O | J14: O
D15: 2 | J15: O
B16: FoodOption
D17: null | G17: O
D18: 1 | H18: O | I18: O | J18: O
D19: 2 | I19: O
D20: 3 | J20: O
B21: Quantity
D22: 1 | E22: 1 | H22: O | I22: O | J22: O
A36: Confirm | B36: Return
B38: Cart List
C39: Cart 1
C40: Product 1:Quantity 1,FoodOption 1: Quantity 1 | F40: O | G40: O
C41: Product 1:Quantity 2,FoodOption 1: Quantity 2 | H41: O | J41: O
C42: Product 1:Quantity 2,FoodOption 1: Quantity 2,FoodOption 2:Quantity 1 | I42: O
C43: Cart 2
C44: Product 2:Quantity 1,FoodOption 3: Quantity 1 | J44: O
B45: Exception
B47: Log message
D48: Thêm vào giỏ hàng thành công | F48: O | H48: O | I48: O | J48: O
D49: Phải chọn Size cho sản phẩm | G49: O
A50: Result | B50: Type(N : Normal, A : Abnormal, B : Boundary) | F50: N | G50: A | H50: N | I50: N | J50: N
B51: Passed/Failed | F51: P | G51: P | H51: P | I51: P | J51: P
B52: Executed Date | F52: 39139 | G52: 39139 | H52: 39139 | I52: 39139 | J52: 39139
B53: Defect ID

Sheet Remove from Cart
A1: Code Module | C1: Cart Management | F1: Method | L1: Remove from Cart
A2: Created By | C2: AnhDQ | F2: Executed By
A3: Test requirement | C3: <Brief description about requirements which are tested in this function>
A4: Passed | C4: Failed | F4: Untested | L4: N/A/B | O4: Total Test Cases
A5: =COUNTIF(F42:HQ42,"P") -> 3 | C5: =COUNTIF(F43:HQ43,"F") -> 0 | F5: =SUM(O5,-A5,-C5) -> 0 | L5: =COUNTIF(E41:HQ41,"N") -> 3 | M5: =COUNTIF(E42:HQ42,"A") -> 0 | N5: =COUNTIF(E42:HQ42,"B") -> 0 | O5: =COUNTA(E7:HT7) -> 3
F7: UTCID01 | G7: UTCID02 | H7: UTCID03
A8: Condition | B8: Precondition
D9: An exsited cart with product id:1,quantity 2,FoodOption id 1,quantity :2
B12: ProductId
D13: null | F13: O | H13: O
D14: 1 | G14: O
B15: FoodOptionId
D16: null | F16: O
D17: 1 | H17: O
A31: Confirm | B31: Return
C32: Cart 1
C33: Product 1:Quantity 2,FoodOption 1: Quantity 2 | F33: O
C34: Product 1:Quantity 2,FoodOption 1: Quantity 1 | H34: O
C35: Null | G35: O
B36: Exception
B38: Log message
D39: "please input a>= -1" | F39: O
A41: Result | B41: Type(N : Normal, A : Abnormal, B : Boundary) | F41: N | G41: N | H41: N
B42: Passed/Failed | F42: P | G42: P | H42: P
B43: Executed Date | F43: 39139 | G43: 39139 | H43: 39139
B44: Defect ID

Sheet View Cart
A1: Code Module | C1: Cart Management | F1: Method | L1: View Cart
A2: Created By | C2: AnhDQ | F2: Executed By
A3: Test requirement | C3: <Brief description about requirements which are tested in this function>
A4: Passed | C4: Failed | F4: Untested | L4: N/A/B | O4: Total Test Cases
A5: =COUNTIF(F39:HQ39,"P") -> 2 | C5: =COUNTIF(F40:HQ40,"F") -> 0 | F5: =SUM(O5,-A5,-C5) -> 0 | L5: =COUNTIF(E38:HQ38,"N") -> 2 | M5: =COUNTIF(E39:HQ39,"A") -> 0 | N5: =COUNTIF(E39:HQ39,"B") -> 0 | O5: =COUNTA(E7:HT7) -> 2
F7: UTCID01 | G7: UTCID02
A8: Condition | B8: Precondition
B11: CartId
D12: null | F12: O
D13: 1 | G13: O
A31: Confirm | B31: Return
D32: T | F32: O | G32: O
D33: F
B35: Log message
A38: Result | B38: Type(N : Normal, A : Abnormal, B : Boundary) | F38: N | G38: N
B39: Passed/Failed | F39: P | G39: P
B40: Executed Date | F40: 39139 | G40: 39139
B41: Defect ID

Sheet View Home Page
A1: Code Module | C1: Common Feature | F1: Method | L1: View Home Page
A2: Created By | C2: AnhDQ | F2: Executed By
A3: Test requirement | C3: <Brief description about requirements which are tested in this function>
A4: Passed | C4: Failed | F4: Untested | L4: N/A/B | O4: Total Test Cases
